<?xml version="1.0" ?>
<!-- =================================================================================== -->
<!-- |    This document was autogenerated by xacro from orthos.xacro                   | -->
<!-- |    EDITING THIS FILE BY HAND IS NOT RECOMMENDED                                 | -->
<!-- =================================================================================== -->
<robot name="orthos">
  <!-- <xacro:include filename="$(find sirius_driver)/urdf/modules/orthos_arm_joint_pub.xacro"/>-->
  <!--<xacro:include filename="$(find sirius_driver)/urdf/modules/orthos_joint_pub.xacro" />

  <xacro:include filename="$(find sirius_driver)/urdf/modules/orthos_drive.xacro" />-->
  <link name="base_link"/>
  <link name="base_frame_link">
    <inertial>
      <origin rpy="0 0 0" xyz="0 0 0"/>
      <mass value="10"/>
      <inertia ixx="0.003" ixy="0" ixz="0" iyy="0.09" iyz="0" izz="0.09"/>
    </inertial>
    <visual>
      <origin rpy="0 0 0" xyz="0 0 0"/>
      <geometry>
        <mesh filename="package://sirius_driver/meshes/base_frame.stl"/>
      </geometry>
      <material name="white">
        <color rgba="1 1 1 1"/>
      </material>
    </visual>
    <collision>
      <origin rpy="0 0 0" xyz="0 0 0"/>
      <geometry>
        <box size="0.8 0.160 0.040"/>
      </geometry>
    </collision>
  </link>
  <joint name="base_frame_joint" type="fixed">
    <origin rpy="0 0 0" xyz="0 0 0"/>
    <parent link="base_link"/>
    <child link="base_frame_link"/>
    <axis xyz="0 0 0"/>
  </joint>
  <!-- Rocker -->
  <link name="orthos_rocker_left">
    <inertial>
      <origin rpy="0 0 0" xyz="0 0 0"/>
      <mass value="1"/>
      <inertia ixx="0.316" ixy="0" ixz="0" iyy="0.166" iyz="0" izz="0.307"/>
    </inertial>
    <visual>
      <origin rpy="0 0 0" xyz="0 0 0"/>
      <geometry>
        <mesh filename="package://sirius_driver/meshes/rocker_left.stl"/>
      </geometry>
      <material name="white">
        <color rgba="1 1 1 1"/>
      </material>
    </visual>
    <collision>
      <origin rpy="0 0 0" xyz="0 0 0"/>
      <geometry>
        <mesh filename="package://sirius_driver/meshes/rocker_left.stl"/>
      </geometry>
    </collision>
  </link>
  <joint name="orthos_rocker_left_joint" type="revolute">
    <origin rpy="0 0 -1.5708" xyz="0.1502 0.24465 -0.060115"/>
    <limit effort="100" lower="-1.5708" upper="1.5708" velocity="3"/>
    <parent link="base_frame_link"/>
    <child link="orthos_rocker_left"/>
    <axis xyz="1 0 0"/>
  </joint>
  <!-- Bogie -->
  <link name="orthos_bogie_left">
    <inertial>
      <origin rpy="0 0 0" xyz="0 0 0"/>
      <mass value="1"/>
      <inertia ixx="0.1" ixy="0" ixz="0" iyy="0.1" iyz="0" izz="0.1"/>
    </inertial>
    <visual>
      <origin rpy="0 0 0" xyz="0 0 0"/>
      <geometry>
        <mesh filename="package://sirius_driver/meshes/bogie_left.stl"/>
      </geometry>
      <material name="white">
        <color rgba="1 1 1 1"/>
      </material>
    </visual>
    <collision>
      <origin rpy="0 0 0" xyz="0 0 0"/>
      <geometry>
        <mesh filename="package://sirius_driver/meshes/bogie_left.stl"/>
      </geometry>
    </collision>
  </link>
  <joint name="orthos_bogie_left_joint" type="revolute">
    <origin rpy="0 0 0" xyz="0 -0.276262 0"/>
    <limit effort="100" lower="-1.5708" upper="1.5708" velocity="3"/>
    <parent link="orthos_rocker_left"/>
    <child link="orthos_bogie_left"/>
    <axis xyz="1 0 0"/>
  </joint>
  <!-- Turn motor front-->
  <link name="orthos_turn_left_front">
    <inertial>
      <origin rpy="0 0 0" xyz="0 0 0"/>
      <mass value="1"/>
      <inertia ixx="0.1" ixy="0" ixz="0" iyy="0.1" iyz="0" izz="0.1"/>
    </inertial>
    <visual>
      <origin rpy="0 0 0" xyz="0 0 0"/>
      <geometry>
        <mesh filename="package://sirius_driver/meshes/turn.stl"/>
      </geometry>
      <material name="white">
        <color rgba="1 1 1 1"/>
      </material>
    </visual>
    <collision>
      <origin rpy="0 0 0" xyz="0 0 0"/>
      <geometry>
        <mesh filename="package://sirius_driver/meshes/turn.stl"/>
      </geometry>
    </collision>
  </link>
  <joint name="orthos_turn_left_front_joint" type="fixed">
    <origin rpy="0 0 0" xyz="0 0.364 -0.097"/>
    <parent link="orthos_rocker_left"/>
    <child link="orthos_turn_left_front"/>
    <axis xyz="0 0 0"/>
  </joint>
  <!-- Motor and wheel mounting-->
  <link name="orthos_motor_left_1">
    <inertial>
      <origin rpy="0 0 0" xyz="0 0 0"/>
      <mass value="1"/>
      <inertia ixx="0.1" ixy="0" ixz="0" iyy="0.1" iyz="0" izz="0.1"/>
    </inertial>
    <visual>
      <origin rpy="0 0 0" xyz="0 0 0"/>
      <geometry>
        <mesh filename="package://sirius_driver/meshes/motor.stl"/>
      </geometry>
      <material name="white">
        <color rgba="1 1 1 1"/>
      </material>
    </visual>
    <collision>
      <origin rpy="0 0 0" xyz="0 0 0"/>
      <geometry>
        <mesh filename="package://sirius_driver/meshes/motor.stl"/>
      </geometry>
    </collision>
  </link>
  <joint name="orthos_motor_left_1_joint" type="revolute">
    <origin rpy="0 0 0" xyz="0 0.04 -0.14"/>
    <limit effort="100" lower="-0.523599" upper="0.523599" velocity="3"/>
    <parent link="orthos_turn_left_front"/>
    <child link="orthos_motor_left_1"/>
    <axis xyz="0 0 1"/>
  </joint>
  <!-- Wheel front -->
  <link name="orthos_wheel_left_1">
    <inertial>
      <origin rpy="0 0 0" xyz="0 0 0"/>
      <mass value="1"/>
      <inertia ixx="0.1" ixy="0" ixz="0" iyy="0.1" iyz="0" izz="0.1"/>
    </inertial>
    <visual>
      <origin rpy="0 0 0" xyz="0 0 0"/>
      <geometry>
        <mesh filename="package://sirius_driver/meshes/wheel.stl"/>
      </geometry>
      <material name="white">
        <color rgba="1 1 1 1"/>
      </material>
    </visual>
    <collision>
      <origin rpy="0 0 0" xyz="0 0 0"/>
      <geometry>
        <mesh filename="package://sirius_driver/meshes/wheel.stl"/>
      </geometry>
    </collision>
  </link>
  <joint name="orthos_wheel_left_1_joint" type="continuous">
    <origin rpy="0 0 0" xyz="0 0 0"/>
    <parent link="orthos_motor_left_1"/>
    <child link="orthos_wheel_left_1"/>
    <axis xyz="1 0 0"/>
  </joint>
  <!-- Motor mid -->
  <link name="orthos_motor_left_2">
    <inertial>
      <origin rpy="0 0 0" xyz="0 0 0"/>
      <mass value="1"/>
      <inertia ixx="0.1" ixy="0" ixz="0" iyy="0.1" iyz="0" izz="0.1"/>
    </inertial>
    <visual>
      <origin rpy="0 0 0" xyz="0 0 0"/>
      <geometry>
        <mesh filename="package://sirius_driver/meshes/motor_mid.stl"/>
      </geometry>
      <material name="white">
        <color rgba="1 1 1 1"/>
      </material>
    </visual>
    <collision>
      <origin rpy="0 0 0" xyz="0 0 0"/>
      <geometry>
        <mesh filename="package://sirius_driver/meshes/motor_mid.stl"/>
      </geometry>
    </collision>
  </link>
  <joint name="orthos_motor_left_2_joint" type="fixed">
    <origin rpy="0 0 0" xyz="-0.0305 0.2852 -0.2205"/>
    <limit effort="100" lower="-0.523599" upper="0.523599" velocity="3"/>
    <parent link="orthos_bogie_left"/>
    <child link="orthos_motor_left_2"/>
    <axis xyz="1 0 0"/>
  </joint>
  <!-- Wheel mid -->
  <link name="orthos_wheel_left_2">
    <inertial>
      <origin rpy="0 0 0" xyz="0 0 0"/>
      <mass value="1"/>
      <inertia ixx="0.1" ixy="0" ixz="0" iyy="0.1" iyz="0" izz="0.1"/>
    </inertial>
    <visual>
      <origin rpy="0 0 0" xyz="0 0 0"/>
      <geometry>
        <mesh filename="package://sirius_driver/meshes/wheel.stl"/>
      </geometry>
      <material name="white">
        <color rgba="1 1 1 1"/>
      </material>
    </visual>
    <collision>
      <origin rpy="0 0 0" xyz="0 0 0"/>
      <geometry>
        <mesh filename="package://sirius_driver/meshes/motor.stl"/>
      </geometry>
    </collision>
  </link>
  <joint name="orthos_wheel_left_2_joint" type="continuous">
    <origin rpy="0 0 0" xyz="-0.055 0 0"/>
    <parent link="orthos_motor_left_2"/>
    <child link="orthos_wheel_left_2"/>
    <axis xyz="1 0 0"/>
  </joint>
  <!-- Turn motor rear -->
  <link name="orthos_turn_left_rear">
    <inertial>
      <origin rpy="0 0 0" xyz="0 0 0"/>
      <mass value="1"/>
      <inertia ixx="0.1" ixy="0" ixz="0" iyy="0.1" iyz="0" izz="0.1"/>
    </inertial>
    <visual>
      <origin rpy="0 0 0" xyz="0 0 0"/>
      <geometry>
        <mesh filename="package://sirius_driver/meshes/turn_rear.stl"/>
      </geometry>
      <material name="white">
        <color rgba="1 1 1 1"/>
      </material>
    </visual>
    <collision>
      <origin rpy="0 0 0" xyz="0 0 0"/>
      <geometry>
        <mesh filename="package://sirius_driver/meshes/turn_rear.stl"/>
      </geometry>
    </collision>
  </link>
  <joint name="orthos_turn_left_rear_joint" type="fixed">
    <origin rpy="0 0 0" xyz="0 -0.217 -0.0653"/>
    <parent link="orthos_bogie_left"/>
    <child link="orthos_turn_left_rear"/>
    <axis xyz="0 0 0"/>
  </joint>
  <!-- Motor and wheel mounting rear-->
  <link name="orthos_motor_left_3">
    <inertial>
      <origin rpy="0 0 0" xyz="0 0 0"/>
      <mass value="1"/>
      <inertia ixx="0.1" ixy="0" ixz="0" iyy="0.1" iyz="0" izz="0.1"/>
    </inertial>
    <visual>
      <origin rpy="0 0 0" xyz="0 0 0"/>
      <geometry>
        <mesh filename="package://sirius_driver/meshes/motor.stl"/>
      </geometry>
      <material name="white">
        <color rgba="1 1 1 1"/>
      </material>
    </visual>
    <collision>
      <origin rpy="0 0 0" xyz="0 0 0"/>
      <geometry>
        <mesh filename="package://sirius_driver/meshes/motor.stl"/>
      </geometry>
    </collision>
  </link>
  <joint name="orthos_motor_left_3_joint" type="revolute">
    <origin rpy="0 0 0" xyz="0 0 -0.15"/>
    <limit effort="100" lower="-0.523599" upper="0.523599" velocity="3"/>
    <parent link="orthos_turn_left_rear"/>
    <child link="orthos_motor_left_3"/>
    <axis xyz="0 0 1"/>
  </joint>
  <link name="orthos_wheel_left_3">
    <inertial>
      <origin rpy="0 0 0" xyz="0 0 0"/>
      <mass value="1"/>
      <inertia ixx="0.1" ixy="0" ixz="0" iyy="0.1" iyz="0" izz="0.1"/>
    </inertial>
    <visual>
      <origin rpy="0 0 0" xyz="0 0 0"/>
      <geometry>
        <mesh filename="package://sirius_driver/meshes/wheel.stl"/>
      </geometry>
      <material name="white">
        <color rgba="1 1 1 1"/>
      </material>
    </visual>
    <collision>
      <origin rpy="0 0 0" xyz="0 0 0"/>
      <geometry>
        <mesh filename="package://sirius_driver/meshes/wheel.stl"/>
      </geometry>
    </collision>
  </link>
  <joint name="orthos_wheel_left_3_joint" type="continuous">
    <origin rpy="0 0 0" xyz="0 0 0"/>
    <parent link="orthos_motor_left_3"/>
    <child link="orthos_wheel_left_3"/>
    <axis xyz="1 0 0"/>
  </joint>
  <transmission name="trans_wheel_left_1">
    <type>transmission_interface/SimpleTransmission</type>
    <joint name="orthos_wheel_left_1_joint">
      <hardwareInterface>hardware_interface/VelocityJointInterface</hardwareInterface>
    </joint>
    <actuator name="motor_wheel_left_1">
      <mechanicalReduction>100</mechanicalReduction>
    </actuator>
  </transmission>
  <transmission name="trans_wheel_left_2">
    <type>transmission_interface/SimpleTransmission</type>
    <joint name="orthos_wheel_left_2_joint">
      <hardwareInterface>hardware_interface/VelocityJointInterface</hardwareInterface>
    </joint>
    <actuator name="motor_wheel_left_2">
      <mechanicalReduction>100</mechanicalReduction>
    </actuator>
  </transmission>
  <transmission name="trans_wheel_left_3">
    <type>transmission_interface/SimpleTransmission</type>
    <joint name="orthos_wheel_left_3_joint">
      <hardwareInterface>hardware_interface/VelocityJointInterface</hardwareInterface>
    </joint>
    <actuator name="motor_wheel_left_3">
      <mechanicalReduction>100</mechanicalReduction>
    </actuator>
  </transmission>
  <transmission name="trans_turn_left_front">
    <type>transmission_interface/SimpleTransmission</type>
    <joint name="orthos_motor_left_1_joint">
      <hardwareInterface>hardware_interface/PositionJointInterface</hardwareInterface>
    </joint>
    <actuator name="motor_turn_left_front">
      <mechanicalReduction>100</mechanicalReduction>
    </actuator>
  </transmission>
  <transmission name="trans_motor_left_rear">
    <type>transmission_interface/SimpleTransmission</type>
    <joint name="orthos_motor_left_3_joint">
      <hardwareInterface>hardware_interface/PositionJointInterface</hardwareInterface>
    </joint>
    <actuator name="motor_turn_left_rear">
      <mechanicalReduction>100</mechanicalReduction>
    </actuator>
  </transmission>
  <link name="orthos_rocker_right">
    <inertial>
      <origin rpy="0 0 0" xyz="0 0 0"/>
      <mass value="1"/>
      <inertia ixx="0.316" ixy="0" ixz="0" iyy="0.166" iyz="0" izz="0.307"/>
    </inertial>
    <visual>
      <origin rpy="0 0 0" xyz="0 0 0"/>
      <geometry>
        <mesh filename="package://sirius_driver/meshes/rocker_right.stl"/>
      </geometry>
      <material name="white">
        <color rgba="1 1 1 1"/>
      </material>
    </visual>
    <collision>
      <origin rpy="0 0 0" xyz="0 0 0"/>
      <geometry>
        <mesh filename="package://sirius_driver/meshes/rocker_right.stl"/>
      </geometry>
    </collision>
  </link>
  <joint name="orthos_rocker_right_joint" type="revolute">
    <origin rpy="0 0 1.5708" xyz="0.1502 -0.24465 -0.060115"/>
    <limit effort="100" lower="-1.5708" upper="1.5708" velocity="3"/>
    <parent link="base_frame_link"/>
    <child link="orthos_rocker_right"/>
    <axis xyz="1 0 0"/>
  </joint>
  <link name="orthos_bogie_right">
    <inertial>
      <origin rpy="0 0 0" xyz="0 0 0"/>
      <mass value="1"/>
      <inertia ixx="0.1" ixy="0" ixz="0" iyy="0.1" iyz="0" izz="0.1"/>
    </inertial>
    <visual>
      <origin rpy="0 0 0" xyz="0 0 0"/>
      <geometry>
        <mesh filename="package://sirius_driver/meshes/bogie_right.stl"/>
      </geometry>
      <material name="white">
        <color rgba="1 1 1 1"/>
      </material>
    </visual>
    <collision>
      <origin rpy="0 0 0" xyz="0 0 0"/>
      <geometry>
        <mesh filename="package://sirius_driver/meshes/bogie_right.stl"/>
      </geometry>
    </collision>
  </link>
  <joint name="orthos_bogie_right_joint" type="revolute">
    <origin rpy="0 0 0" xyz="0 0.276262 0"/>
    <limit effort="100" lower="-1.5708" upper="1.5708" velocity="3"/>
    <parent link="orthos_rocker_right"/>
    <child link="orthos_bogie_right"/>
    <axis xyz="1 0 0"/>
  </joint>
  <link name="orthos_turn_right_front">
    <inertial>
      <origin rpy="0 0 0" xyz="0 0 0"/>
      <mass value="1"/>
      <inertia ixx="0.1" ixy="0" ixz="0" iyy="0.1" iyz="0" izz="0.1"/>
    </inertial>
    <visual>
      <origin rpy="0 0 0" xyz="0 0 0"/>
      <geometry>
        <mesh filename="package://sirius_driver/meshes/turn.stl"/>
      </geometry>
      <material name="white">
        <color rgba="1 1 1 1"/>
      </material>
    </visual>
    <collision>
      <origin rpy="0 0 0" xyz="0 0 0"/>
      <geometry>
        <mesh filename="package://sirius_driver/meshes/turn.stl"/>
      </geometry>
    </collision>
  </link>
  <joint name="orthos_turn_right_front_joint" type="fixed">
    <origin rpy="0 0 3.1415" xyz="0 -0.364 -0.097"/>
    <parent link="orthos_rocker_right"/>
    <child link="orthos_turn_right_front"/>
    <axis xyz="0 0 0"/>
  </joint>
  <link name="orthos_motor_right_1">
    <inertial>
      <origin rpy="0 0 0" xyz="0 0 0"/>
      <mass value="1"/>
      <inertia ixx="0.1" ixy="0" ixz="0" iyy="0.1" iyz="0" izz="0.1"/>
    </inertial>
    <visual>
      <origin rpy="0 0 0" xyz="0 0 0"/>
      <geometry>
        <mesh filename="package://sirius_driver/meshes/motor.stl"/>
      </geometry>
      <material name="white">
        <color rgba="1 1 1 1"/>
      </material>
    </visual>
    <collision>
      <origin rpy="0 0 0" xyz="0 0 0"/>
      <geometry>
        <mesh filename="package://sirius_driver/meshes/motor.stl"/>
      </geometry>
    </collision>
  </link>
  <joint name="orthos_motor_right_1_joint" type="revolute">
    <origin rpy="0 0 3.1415" xyz="0 0.04 -0.14"/>
    <limit effort="100" lower="-0.523599" upper="0.523599" velocity="3"/>
    <parent link="orthos_turn_right_front"/>
    <child link="orthos_motor_right_1"/>
    <axis xyz="0 0 1"/>
  </joint>
  <link name="orthos_wheel_right_1">
    <inertial>
      <origin rpy="0 0 0" xyz="0 0 0"/>
      <mass value="1"/>
      <inertia ixx="0.1" ixy="0" ixz="0" iyy="0.1" iyz="0" izz="0.1"/>
    </inertial>
    <visual>
      <origin rpy="0 0 0" xyz="0 0 0"/>
      <geometry>
        <mesh filename="package://sirius_driver/meshes/wheel.stl"/>
      </geometry>
      <material name="white">
        <color rgba="1 1 1 1"/>
      </material>
    </visual>
    <collision>
      <origin rpy="0 0 0" xyz="0 0 0"/>
      <geometry>
        <mesh filename="package://sirius_driver/meshes/wheel.stl"/>
      </geometry>
    </collision>
  </link>
  <joint name="orthos_wheel_right_1_joint" type="continuous">
    <origin rpy="0 0 0" xyz="0 0 0"/>
    <parent link="orthos_motor_right_1"/>
    <child link="orthos_wheel_right_1"/>
    <axis xyz="1 0 0"/>
  </joint>
  <link name="orthos_motor_right_2">
    <inertial>
      <origin rpy="0 0 0" xyz="0 0 0"/>
      <mass value="1"/>
      <inertia ixx="0.1" ixy="0" ixz="0" iyy="0.1" iyz="0" izz="0.1"/>
    </inertial>
    <visual>
      <origin rpy="0 0 0" xyz="0 0 0"/>
      <geometry>
        <mesh filename="package://sirius_driver/meshes/motor_mid.stl"/>
      </geometry>
      <material name="white">
        <color rgba="1 1 1 1"/>
      </material>
    </visual>
    <collision>
      <origin rpy="0 0 0" xyz="0 0 0"/>
      <geometry>
        <mesh filename="package://sirius_driver/meshes/motor_mid.stl"/>
      </geometry>
    </collision>
  </link>
  <joint name="orthos_motor_right_2_joint" type="fixed">
    <origin rpy="-1.97920340718 0 0" xyz="-0.0305 -0.2852 -0.2205"/>
    <limit effort="100" lower="-0.523599" upper="0.523599" velocity="3"/>
    <parent link="orthos_bogie_right"/>
    <child link="orthos_motor_right_2"/>
    <axis xyz="1 0 0"/>
  </joint>
  <link name="orthos_wheel_right_2">
    <inertial>
      <origin rpy="0 0 0" xyz="0 0 0"/>
      <mass value="1"/>
      <inertia ixx="0.1" ixy="0" ixz="0" iyy="0.1" iyz="0" izz="0.1"/>
    </inertial>
    <visual>
      <origin rpy="0 0 0" xyz="0 0 0"/>
      <geometry>
        <mesh filename="package://sirius_driver/meshes/wheel.stl"/>
      </geometry>
      <material name="white">
        <color rgba="1 1 1 1"/>
      </material>
    </visual>
    <collision>
      <origin rpy="0 0 0" xyz="0 0 0"/>
      <geometry>
        <mesh filename="package://sirius_driver/meshes/motor.stl"/>
      </geometry>
    </collision>
  </link>
  <joint name="orthos_wheel_right_2_joint" type="continuous">
    <origin rpy="0 0 0" xyz="-0.055 0 0"/>
    <parent link="orthos_motor_right_2"/>
    <child link="orthos_wheel_right_2"/>
    <axis xyz="1 0 0"/>
  </joint>
  <link name="orthos_turn_right_rear">
    <inertial>
      <origin rpy="0 0 0" xyz="0 0 0"/>
      <mass value="1"/>
      <inertia ixx="0.1" ixy="0" ixz="0" iyy="0.1" iyz="0" izz="0.1"/>
    </inertial>
    <visual>
      <origin rpy="0 0 0" xyz="0 0 0"/>
      <geometry>
        <mesh filename="package://sirius_driver/meshes/turn_rear.stl"/>
      </geometry>
      <material name="white">
        <color rgba="1 1 1 1"/>
      </material>
    </visual>
    <collision>
      <origin rpy="0 0 0" xyz="0 0 0"/>
      <geometry>
        <mesh filename="package://sirius_driver/meshes/turn_rear.stl"/>
      </geometry>
    </collision>
  </link>
  <joint name="orthos_turn_right_rear_joint" type="fixed">
    <origin rpy="0 0 3.1415" xyz="0 0.217 -0.0653"/>
    <parent link="orthos_bogie_right"/>
    <child link="orthos_turn_right_rear"/>
    <axis xyz="0 0 0"/>
  </joint>
  <link name="orthos_motor_right_3">
    <inertial>
      <origin rpy="0 0 0" xyz="0 0 0"/>
      <mass value="1"/>
      <inertia ixx="0.1" ixy="0" ixz="0" iyy="0.1" iyz="0" izz="0.1"/>
    </inertial>
    <visual>
      <origin rpy="0 0 0" xyz="0 0 0"/>
      <geometry>
        <mesh filename="package://sirius_driver/meshes/motor.stl"/>
      </geometry>
      <material name="white">
        <color rgba="1 1 1 1"/>
      </material>
    </visual>
    <collision>
      <origin rpy="0 0 0" xyz="0 0 0"/>
      <geometry>
        <mesh filename="package://sirius_driver/meshes/motor.stl"/>
      </geometry>
    </collision>
  </link>
  <joint name="orthos_motor_right_3_joint" type="revolute">
    <origin rpy="0 0 3.1415" xyz="0 0 -0.15"/>
    <limit effort="100" lower="-0.523599" upper="0.523599" velocity="3"/>
    <parent link="orthos_turn_right_rear"/>
    <child link="orthos_motor_right_3"/>
    <axis xyz="0 0 1"/>
  </joint>
  <link name="orthos_wheel_right_3">
    <inertial>
      <origin rpy="0 0 0" xyz="0 0 0"/>
      <mass value="1"/>
      <inertia ixx="0.1" ixy="0" ixz="0" iyy="0.1" iyz="0" izz="0.1"/>
    </inertial>
    <visual>
      <origin rpy="0 0 0" xyz="0 0 0"/>
      <geometry>
        <mesh filename="package://sirius_driver/meshes/wheel.stl"/>
      </geometry>
      <material name="white">
        <color rgba="1 1 1 1"/>
      </material>
    </visual>
    <collision>
      <origin rpy="0 0 0" xyz="0 0 0"/>
      <geometry>
        <mesh filename="package://sirius_driver/meshes/wheel.stl"/>
      </geometry>
    </collision>
  </link>
  <joint name="orthos_wheel_right_3_joint" type="continuous">
    <origin rpy="0 0 0" xyz="0 0 0"/>
    <parent link="orthos_motor_right_3"/>
    <child link="orthos_wheel_right_3"/>
    <axis xyz="1 0 0"/>
  </joint>
  <transmission name="trans_wheel_right_1">
    <type>transmission_interface/SimpleTransmission</type>
    <joint name="orthos_wheel_right_1_joint">
      <hardwareInterface>hardware_interface/VelocityJointInterface</hardwareInterface>
      <!-- <hardwareInterface>hardware_interface/EffortJointInterface</hardwareInterface> 
      Just with RobotHW, not with Gazebo-->
    </joint>
    <actuator name="motor_wheel_right_1">
      <mechanicalReduction>100</mechanicalReduction>
    </actuator>
  </transmission>
  <transmission name="trans_wheel_right_2">
    <type>transmission_interface/SimpleTransmission</type>
    <joint name="orthos_wheel_right_2_joint">
      <hardwareInterface>hardware_interface/VelocityJointInterface</hardwareInterface>
    </joint>
    <actuator name="motor_wheel_right_2">
      <mechanicalReduction>100</mechanicalReduction>
    </actuator>
  </transmission>
  <transmission name="trans_wheel_right_3">
    <type>transmission_interface/SimpleTransmission</type>
    <joint name="orthos_wheel_right_3_joint">
      <hardwareInterface>hardware_interface/VelocityJointInterface</hardwareInterface>
    </joint>
    <actuator name="motor_wheel_right_3">
      <mechanicalReduction>100</mechanicalReduction>
    </actuator>
  </transmission>
  <transmission name="trans_turn_right_front">
    <type>transmission_interface/SimpleTransmission</type>
    <joint name="orthos_motor_right_1_joint">
      <hardwareInterface>hardware_interface/PositionJointInterface</hardwareInterface>
    </joint>
    <actuator name="motor_turn_right_front">
      <mechanicalReduction>100</mechanicalReduction>
    </actuator>
  </transmission>
  <transmission name="trans_turn_right_rear">
    <type>transmission_interface/SimpleTransmission</type>
    <joint name="orthos_motor_right_3_joint">
      <hardwareInterface>hardware_interface/PositionJointInterface</hardwareInterface>
    </joint>
    <actuator name="motor_wheel_right_3">
      <mechanicalReduction>100</mechanicalReduction>
    </actuator>
  </transmission>
  <link name="virtual_link_1">
    <inertial>
      <mass value="0.025"/>
      <inertia ixx="5.8083e-4" ixy="0" ixz="0" iyy="3.0833e-5" iyz="0" izz="5.9083e-4"/>
    </inertial>
  </link>
  <link name="virtual_link_2">
    <inertial>
      <mass value="0.025"/>
      <inertia ixx="5.8083e-4" ixy="0" ixz="0" iyy="3.0833e-5" iyz="0" izz="5.9083e-4"/>
    </inertial>
  </link>
  <link name="virtual_link_3">
    <inertial>
      <mass value="0.025"/>
      <inertia ixx="5.8083e-4" ixy="0" ixz="0" iyy="3.0833e-5" iyz="0" izz="5.9083e-4"/>
    </inertial>
  </link>
  <link name="virtual_link_4">
    <inertial>
      <mass value="0.025"/>
      <inertia ixx="5.8083e-4" ixy="0" ixz="0" iyy="3.0833e-5" iyz="0" izz="5.9083e-4"/>
    </inertial>
  </link>
  <joint name="right_rocker_virtual_1" type="revolute">
    <origin rpy="0 0 0" xyz="0 0.002 0.095"/>
    <limit effort="100" lower="-0.349066" upper="0.349066" velocity="3"/>
    <parent link="orthos_rocker_right"/>
    <child link="virtual_link_1"/>
    <axis xyz="1 0 0"/>
  </joint>
  <joint name="virtual_1_2" type="revolute">
    <origin rpy="0 0 0" xyz="0 0 0"/>
    <limit effort="100" lower="-0.349066" upper="0.349066" velocity="3"/>
    <parent link="virtual_link_1"/>
    <child link="virtual_link_2"/>
    <axis xyz="0 1 0"/>
  </joint>
  <link name="orthos_spanner_right">
    <inertial>
      <origin rpy="0 0 0" xyz="0 0 0"/>
      <mass value="1"/>
      <inertia ixx="0.1" ixy="0" ixz="0" iyy="0.1" iyz="0" izz="0.1"/>
    </inertial>
    <visual>
      <origin rpy="0 0 0" xyz="0 0 0"/>
      <geometry>
        <mesh filename="package://sirius_driver/meshes/spanner.stl"/>
      </geometry>
      <material name="white">
        <color rgba="1 1 1 1"/>
      </material>
    </visual>
    <collision>
      <origin rpy="0 0 0" xyz="0 0 0"/>
      <geometry>
        <mesh filename="package://sirius_driver/meshes/spanner.stl"/>
      </geometry>
    </collision>
  </link>
  <joint name="virtual_2_spanner_right" type="revolute">
    <origin rpy="0 0 0" xyz="0 0 0"/>
    <limit effort="100" lower="-0.349066" upper="0.349066" velocity="3"/>
    <parent link="virtual_link_2"/>
    <child link="orthos_spanner_right"/>
    <axis xyz="0 0 1"/>
  </joint>
  <joint name="spanner_right_virtual_3" type="revolute">
    <origin rpy="0 0 0" xyz="0 0.1505 0"/>
    <limit effort="100" lower="-0.349066" upper="0.349066" velocity="3"/>
    <parent link="orthos_spanner_right"/>
    <child link="virtual_link_3"/>
    <axis xyz="1 0 0"/>
  </joint>
  <joint name="rotbar_virtual_4" type="revolute">
    <origin rpy="0 0 0" xyz="0 0.235 0"/>
    <limit effort="100" lower="-0.349066" upper="0.349066" velocity="3"/>
    <parent link="orthos_rotbar"/>
    <child link="virtual_link_4"/>
    <axis xyz="1 0 0"/>
    <!-- X axis of base_frame is y-axis of right_rocker which should be the axis here-->
  </joint>
  <link name="virtual_link_5">
    <inertial>
      <mass value="0.025"/>
      <inertia ixx="5.8083e-4" ixy="0" ixz="0" iyy="3.0833e-5" iyz="0" izz="5.9083e-4"/>
    </inertial>
  </link>
  <link name="virtual_link_6">
    <inertial>
      <mass value="0.025"/>
      <inertia ixx="5.8083e-4" ixy="0" ixz="0" iyy="3.0833e-5" iyz="0" izz="5.9083e-4"/>
    </inertial>
  </link>
  <link name="virtual_link_7">
    <inertial>
      <mass value="0.025"/>
      <inertia ixx="5.8083e-4" ixy="0" ixz="0" iyy="3.0833e-5" iyz="0" izz="5.9083e-4"/>
    </inertial>
  </link>
  <link name="virtual_link_8">
    <inertial>
      <mass value="0.025"/>
      <inertia ixx="5.8083e-4" ixy="0" ixz="0" iyy="3.0833e-5" iyz="0" izz="5.9083e-4"/>
    </inertial>
  </link>
  <joint name="left_rocker_virtual_5" type="revolute">
    <origin rpy="0 0 0" xyz="0 -0.002 0.095"/>
    <limit effort="100" lower="-0.349066" upper="0.349066" velocity="3"/>
    <parent link="orthos_rocker_left"/>
    <child link="virtual_link_5"/>
    <axis xyz="1 0 0"/>
  </joint>
  <joint name="virtual_5_6" type="revolute">
    <origin rpy="0 0 0" xyz="0 0 0"/>
    <limit effort="100" lower="-0.349066" upper="0.349066" velocity="3"/>
    <parent link="virtual_link_5"/>
    <child link="virtual_link_6"/>
    <axis xyz="0 1 0"/>
  </joint>
  <link name="orthos_spanner_left">
    <inertial>
      <origin rpy="0 0 0" xyz="0 0 0"/>
      <mass value="1"/>
      <inertia ixx="0.1" ixy="0" ixz="0" iyy="0.1" iyz="0" izz="0.1"/>
    </inertial>
    <visual>
      <origin rpy="0 0 0" xyz="0 0 0"/>
      <geometry>
        <mesh filename="package://sirius_driver/meshes/spanner.stl"/>
      </geometry>
      <material name="white">
        <color rgba="1 1 1 1"/>
      </material>
    </visual>
    <collision>
      <origin rpy="0 0 0" xyz="0 0 0"/>
      <geometry>
        <mesh filename="package://sirius_driver/meshes/spanner.stl"/>
      </geometry>
    </collision>
  </link>
  <joint name="virtual_6_spanner_left" type="revolute">
    <origin rpy="3.1415 0 0" xyz="0 0 0"/>
    <limit effort="100" lower="-0.349066" upper="0.349066" velocity="3"/>
    <parent link="virtual_link_6"/>
    <child link="orthos_spanner_left"/>
    <axis xyz="0 0 1"/>
  </joint>
  <joint name="spanner_left_virtual_7" type="revolute">
    <origin rpy="0 0 0" xyz="0 0.1505 0"/>
    <limit effort="100" lower="-0.349066" upper="0.349066" velocity="3"/>
    <parent link="orthos_spanner_left"/>
    <child link="virtual_link_7"/>
    <axis xyz="1 0 0"/>
  </joint>
  <joint name="rotbar_virtual_8" type="revolute">
    <origin rpy="0 0 0" xyz="0 -0.235 0"/>
    <limit effort="100" lower="-0.349066" upper="0.349066" velocity="3"/>
    <parent link="orthos_rotbar"/>
    <child link="virtual_link_8"/>
    <axis xyz="1 0 0"/>
    <!-- X axis of base_frame is y-axis of right_rocker which should be the axis here-->
  </joint>
  <!-- Base frame to rotbar -->
  <link name="orthos_rotbar">
    <inertial>
      <origin rpy="0 0 0" xyz="0 0 0"/>
      <mass value="1"/>
      <inertia ixx="0.1" ixy="0" ixz="0" iyy="0.1" iyz="0" izz="0.1"/>
    </inertial>
    <visual>
      <origin rpy="0 0 0" xyz="0 0 0"/>
      <geometry>
        <mesh filename="package://sirius_driver/meshes/rotbar.stl"/>
      </geometry>
      <material name="white">
        <color rgba="1 1 1 1"/>
      </material>
    </visual>
    <collision>
      <origin rpy="0 0 0" xyz="0 0 0"/>
      <geometry>
        <mesh filename="package://sirius_driver/meshes/rotbar.stl"/>
      </geometry>
    </collision>
  </link>
  <joint name="orthos_rotbar_joint" type="revolute">
    <origin rpy="0 0 0" xyz="0 0 0.045"/>
    <limit effort="100" lower="-1.5708" upper="1.5708" velocity="3"/>
    <parent link="base_frame_link"/>
    <child link="orthos_rotbar"/>
    <axis xyz="0 0 1"/>
  </joint>
  <!-- Right spanner to differential and loop with base_frame-->
  <gazebo>
    <joint name="closed_loop_joint_right" type="revolute">
      <parent>virtual_link_4</parent>
      <child>virtual_link_3</child>
      <pose>0 0 0 0 0 0</pose>
      <axis>
        <xyz>1 0 0</xyz>
      </axis>
    </joint>
  </gazebo>
  <!-- Left spanner to differential and loop with base_frame-->
  <gazebo>
    <joint name="closed_loop_joint_left" type="revolute">
      <parent>virtual_link_8</parent>
      <child>virtual_link_7</child>
      <pose>0 0 0 0 0 0</pose>
      <axis>
        <xyz>1 0 0</xyz>
      </axis>
    </joint>
  </gazebo>
  <link name="camera_mast">
    <inertial>
      <origin rpy="0 0 0" xyz="0 0 0"/>
      <mass value="2.56"/>
      <inertia ixx="0.007" ixy="0" ixz="0" iyy="0.008" iyz="0" izz="0.014"/>
    </inertial>
    <visual>
      <origin rpy="0 0 0" xyz="0 0 0"/>
      <geometry>
        <mesh filename="package://sirius_driver/meshes/camera_mast.stl"/>
      </geometry>
      <material name="white">
        <color rgba="1 1 1 1"/>
      </material>
    </visual>
    <collision>
      <origin rpy="0 0 0" xyz="0.08 0 -0.025"/>
      <geometry>
        <mesh filename="package://sirius_driver/meshes/camera_mast.stl"/>
      </geometry>
    </collision>
  </link>
  <joint name="camera_mast_joint" type="fixed">
    <origin rpy="0 0 -1.5708" xyz="-0.1155 0 -0.1559"/>
    <parent link="base_frame_link"/>
    <child link="camera_mast"/>
    <axis xyz="0 0 0"/>
  </joint>
  <link name="mounting_plate">
    <inertial>
      <origin rpy="0 0 0" xyz="0 0 0"/>
      <mass value="4.35"/>
      <inertia ixx="0.133" ixy="0" ixz="0" iyy="0.278" iyz="0" izz="0.410"/>
    </inertial>
    <visual>
      <origin rpy="0 0 0" xyz="0 0 0"/>
      <geometry>
        <mesh filename="package://sirius_driver/meshes/mounting_plate.stl"/>
      </geometry>
      <material name="white">
        <color rgba="1 1 1 1"/>
      </material>
    </visual>
    <collision>
      <origin rpy="0 0 0" xyz="0 0 0"/>
      <geometry>
        <mesh filename="package://sirius_driver/meshes/mounting_plate.stl"/>
      </geometry>
    </collision>
  </link>
  <joint name="mounting_plate_joint" type="fixed">
    <origin rpy="0 0 0" xyz="0.12284 0 -0.19806"/>
    <parent link="base_frame_link"/>
    <child link="mounting_plate"/>
    <axis xyz="0 0 0"/>
  </joint>
  <!--<orthos_joint_pub joints='orthos_wheel_left_3_joint, orthos_wheel_right_3_joint, orthos_wheel_left_1_joint, orthos_wheel_right_1_joint'		/>-->
  <!--<orthos_drive/>-->
</robot>
