<?xml version="1.0"?>

<robot xmlns:xacro="http://ros.org/wiki/xacro" name="orthos_differential">    
<xacro:macro name="orthos_differential">

  <link name="virtual_link_1">
    <inertial>
      <mass value="0.025" />
      <inertia ixx="5.8083e-4" ixy="0" ixz="0" iyy="3.0833e-5" iyz="0" izz="5.9083e-4" />
    </inertial>
  </link>

   <link name="virtual_link_2">
    <inertial>
      <mass value="0.025" />
      <inertia ixx="5.8083e-4" ixy="0" ixz="0" iyy="3.0833e-5" iyz="0" izz="5.9083e-4" />
    </inertial>
  </link>

   <link name="virtual_link_3">
    <inertial>
      <mass value="0.025" />
      <inertia ixx="5.8083e-4" ixy="0" ixz="0" iyy="3.0833e-5" iyz="0" izz="5.9083e-4" />
    </inertial>
  </link>

   <link name="virtual_link_4">
    <inertial>
      <mass value="0.025" />
      <inertia ixx="5.8083e-4" ixy="0" ixz="0" iyy="3.0833e-5" iyz="0" izz="5.9083e-4" />
    </inertial>
  </link>

   <joint name="right_rocker_virtual_1" type="revolute">
    <origin xyz="0 0.002 0.095" rpy="0 0 0"/>
    <limit lower="-0.349066" upper="0.349066" effort="100" velocity="3"/>
    <parent link="orthos_rocker_right"/>
    <child link="virtual_link_1"/>
    <axis xyz="1 0 0" />
  </joint>

   <joint name="virtual_1_2" type="revolute">
    <origin xyz="0 0 0" rpy="0 0 0"/>
    <limit lower="-0.349066" upper="0.349066" effort="100" velocity="3"/>
    <parent link="virtual_link_1"/>
    <child link="virtual_link_2"/>
    <axis xyz="0 1 0" />
  </joint>

     <link name="orthos_spanner_right">
    <inertial>
      <origin xyz="0 0 0" rpy="0 0 0" />
       <mass value="1" /> 
      <inertia ixx="0.1" ixy="0" ixz="0" iyy="0.1" iyz="0" izz="0.1" />
    </inertial>
    <visual>
      <origin xyz="0 0 0" rpy="0 0 0" />
      <geometry>
        <mesh filename="package://orthos_description/meshes/spanner.stl" />
      </geometry>
      <material name="white">
        <color rgba="1 1 1 1"/>
      </material>
    </visual>
    <collision>
      <origin xyz="0 0 0" rpy="0 0 0" />
      <geometry>
        <mesh filename="package://orthos_description/meshes/spanner.stl" />
      </geometry>
    </collision>
  </link>

   <joint name="virtual_2_spanner_right" type="revolute">
    <origin xyz="0 0 0" rpy="0 0 0"/>
    <limit lower="-0.349066" upper="0.349066" effort="100" velocity="3"/>  
    <parent link="virtual_link_2" />
    <child link="orthos_spanner_right" />
    <axis xyz="0 0 1" />
  </joint>

  <joint name="spanner_right_virtual_3" type="revolute">
    <origin xyz="0 0.1505 0" rpy="0 0 0"/>
    <limit lower="-0.349066" upper="0.349066" effort="100" velocity="3"/>
    <parent link="orthos_spanner_right" />
    <child link="virtual_link_3" />
    <axis xyz="1 0 0" />
  </joint>

    <joint name="rotbar_virtual_4" type="revolute">
    <origin xyz="0 0.235 0" rpy="0 0 0"/>
    <limit lower="-0.349066" upper="0.349066" effort="100" velocity="3"/>
    <parent link="orthos_rotbar" />
    <child link="virtual_link_4" />
    <axis xyz="1 0 0" /> <!-- X axis of base_frame is y-axis of right_rocker which should be the axis here-->
  </joint>

  <link name="virtual_link_5">
    <inertial>
      <mass value="0.025" />
      <inertia ixx="5.8083e-4" ixy="0" ixz="0" iyy="3.0833e-5" iyz="0" izz="5.9083e-4" />
    </inertial>
  </link>

   <link name="virtual_link_6">
    <inertial>
      <mass value="0.025" />
      <inertia ixx="5.8083e-4" ixy="0" ixz="0" iyy="3.0833e-5" iyz="0" izz="5.9083e-4" />
    </inertial>
  </link>

   <link name="virtual_link_7">
    <inertial>
      <mass value="0.025" />
      <inertia ixx="5.8083e-4" ixy="0" ixz="0" iyy="3.0833e-5" iyz="0" izz="5.9083e-4" />
    </inertial>
  </link>

   <link name="virtual_link_8">
    <inertial>
      <mass value="0.025" />
      <inertia ixx="5.8083e-4" ixy="0" ixz="0" iyy="3.0833e-5" iyz="0" izz="5.9083e-4" />
    </inertial>
  </link>

   <joint name="left_rocker_virtual_5" type="revolute">
    <origin xyz="0 -0.002 0.095" rpy="0 0 0"/>
    <limit lower="-0.349066" upper="0.349066" effort="100" velocity="3"/>
    <parent link="orthos_rocker_left"/>
    <child link="virtual_link_5"/>
    <axis xyz="1 0 0" />
  </joint>

   <joint name="virtual_5_6" type="revolute">
    <origin xyz="0 0 0" rpy="0 0 0"/>
    <limit lower="-0.349066" upper="0.349066" effort="100" velocity="3"/>
    <parent link="virtual_link_5"/>
    <child link="virtual_link_6"/>
    <axis xyz="0 1 0" />
  </joint>

     <link name="orthos_spanner_left">
    <inertial>
      <origin xyz="0 0 0" rpy="0 0 0" />
       <mass value="1" /> 
      <inertia ixx="0.1" ixy="0" ixz="0" iyy="0.1" iyz="0" izz="0.1" />
    </inertial>
    <visual>
      <origin xyz="0 0 0" rpy="0 0 0" />
      <geometry>
        <mesh filename="package://orthos_description/meshes/spanner.stl" />
      </geometry>
      <material name="white">
        <color rgba="1 1 1 1"/>
      </material>
    </visual>
    <collision>
      <origin xyz="0 0 0" rpy="0 0 0" />
      <geometry>
        <mesh filename="package://orthos_description/meshes/spanner.stl" />
      </geometry>
    </collision>
  </link>

   <joint name="virtual_6_spanner_left" type="revolute">
    <origin xyz="0 0 0" rpy="3.1415 0 0"/>
     <limit lower="-0.349066" upper="0.349066" effort="100" velocity="3"/>  
    <parent link="virtual_link_6" />
    <child link="orthos_spanner_left" />
    <axis xyz="0 0 1" />
  </joint>

  <joint name="spanner_left_virtual_7" type="revolute">
    <origin xyz="0 0.1505 0" rpy="0 0 0"/>
    <limit lower="-0.349066" upper="0.349066" effort="100" velocity="3"/>
    <parent link="orthos_spanner_left" />
    <child link="virtual_link_7" />
    <axis xyz="1 0 0" />
  </joint>

    <joint name="rotbar_virtual_8" type="revolute">
    <origin xyz="0 -0.235 0" rpy="0 0 0"/>
    <limit lower="-0.349066" upper="0.349066" effort="100" velocity="3"/>
    <parent link="orthos_rotbar" />
    <child link="virtual_link_8" />
    <axis xyz="1 0 0" /> <!-- X axis of base_frame is y-axis of right_rocker which should be the axis here-->
  </joint>

<!-- Base frame to rotbar -->
    <link name="orthos_rotbar">
    <inertial>
      <origin xyz="0 0 0" rpy="0 0 0" />
       <mass value="1" /> 
      <inertia ixx="0.1" ixy="0" ixz="0" iyy="0.1" iyz="0" izz="0.1" />
    </inertial>
    <visual>
      <origin xyz="0 0 0" rpy="0 0 0" />
      <geometry>
        <mesh filename="package://orthos_description/meshes/rotbar.stl" />
      </geometry>
      <material name="white">
        <color rgba="1 1 1 1"/>
      </material>
    </visual>
    <collision>
      <origin xyz="0 0 0" rpy="0 0 0" />
      <geometry>
        <mesh filename="package://orthos_description/meshes/rotbar.stl" />
      </geometry>
    </collision>
  </link>

<joint name="orthos_rotbar_joint" type="revolute">
    <origin xyz="0 0 0.045" rpy="0 0 0"/>
    <limit lower="-1.5708" upper="1.5708" effort="100" velocity="3"/>
    <parent link="base_frame_link" />
    <child link="orthos_rotbar" />
    <axis xyz="0 0 1" />
  </joint>

<!-- Right spanner to differential and loop with base_frame-->
     <gazebo>
        <joint name="closed_loop_joint_right" type="revolute">
            <parent>virtual_link_4</parent>
            <child>virtual_link_3</child>
            <pose>0 0 0 0 0 0</pose>
            <axis>
                <xyz>1 0 0</xyz>
            </axis>
        </joint>
    </gazebo>
    
    <!-- Left spanner to differential and loop with base_frame-->
         <gazebo>
        <joint name="closed_loop_joint_left" type="revolute">
            <parent>virtual_link_8</parent>
            <child>virtual_link_7</child>
            <pose>0 0 0 0 0 0</pose>
            <axis>
                <xyz>1 0 0</xyz>
            </axis>
        </joint>
    </gazebo>


</xacro:macro>
</robot>
