<?xml version="1.0" ?>
<!-- =================================================================================== -->
<!-- |    This document was autogenerated by xacro from rogue_des.urdf                 | -->
<!-- |    EDITING THIS FILE BY HAND IS NOT RECOMMENDED                                 | -->
<!-- =================================================================================== -->
<!-- This URDF was automatically created by SolidWorks to URDF Exporter! Originally created by Stephen Brawner (brawner@gmail.com) 
     Commit Version: 1.6.0-4-g7f85cfe  Build Version: 1.6.7995.38578
     For more information, please see http://wiki.ros.org/sw_urdf_exporter -->
<robot name="rogue">
  <link name="base_link">
    <origin rpy="0 0 0" xyz="0 0 0"/>
  </link>
  <!-- joint base chassis -->
  <joint name="base_joint" type="fixed">
    <parent link="base_link"/>
    <child link="chassis_link"/>
    <origin xyz="0 -0.235 -0.11"/>
  </joint>
  <!-- chassis link -->
  <link name="chassis_link">
    <inertial>
      <origin rpy="0 0 0" xyz="-0.00246940894159626 0.1058972543147 5.46494556407368E-17"/>
      <mass value="136.620754096564"/>
      <inertia ixx="0.07413" ixy="-0.00011285" ixz="-1.4435E-06" iyy="0.14749" iyz="1.7539E-08" izz="0.11937"/>
    </inertial>
    <visual>
    <origin rpy="0 0 0" xyz="0 0.235 0.11"/>
      <geometry>
        <mesh filename="package://rogue/description/meshes/base_link.stl"/>
      </geometry>
      <material name="">
        <color rgba="0.79216 0.81961 0.93333 1"/>
      </material>
    </visual>
    <collision>
      <origin rpy="0 0 0" xyz="0 0.235 0.11"/>
      <geometry>
        <mesh filename="package://rogue/description/meshes/base_link.stl"/>
      </geometry>
    </collision>
  </link>
  <link name="Steering_Front_Left_Link">
    <inertial>
      <origin rpy="0 0 0" xyz="-0.00974656428371329 0.171466468601951 3.33066907387547E-15"/>
      <mass value="1.85682341940371"/>
      <inertia ixx="0.0307102115747056" ixy="0.00225357611286934" ixz="1.56419202677199E-14" iyy="0.0217734903548105" iyz="-1.09535590233495E-15" izz="0.0500272192704002"/>
    </inertial>
    <visual>
      <origin rpy="0 0 0" xyz="0 0 0"/>
      <geometry>
        <mesh filename="package://rogue/description/meshes/Steering_Front_Left_Link.stl"/>
      </geometry>
      <material name="">
        <color rgba="0.666666666666667 0.698039215686274 0.768627450980392 1"/>
      </material>
    </visual>
    <collision>
      <origin rpy="0 0 0" xyz="0 0 0"/>
      <geometry>
        <mesh filename="package://rogue/description/meshes/Steering_Front_Left_Link.stl"/>
      </geometry>
    </collision>
  </link>
  <joint name="Steering_Front_Left" type="continuous">
    <origin rpy="-1.5789896816345 0 -1.5707963267949" xyz="-0.539929731609329 -0.307999999999972 -0.0838046685206459"/>
    <parent link="base_link"/>
    <child link="Steering_Front_Left_Link"/>
    <axis xyz="0 1 0"/>
  </joint>
  <link name="Driving_Front_Left_Link">
    <inertial>
      <origin rpy="0 0 0" xyz="0.000635564712824666 -0.152689840468291 -0.00010385666276358"/>
      <mass value="3.92591214810011"/>
      <inertia ixx="0.040527651338497" ixy="8.45389473885711E-07" ixz="-3.83041768788121E-09" iyy="0.0313134736150526" iyz="8.54177538313404E-06" izz="0.0312863477526415"/>
    </inertial>
    <visual>
      <origin rpy="0 0 0" xyz="0 0.148 0"/>
      <geometry>
        <mesh filename="package://rogue/description/meshes/Driving_Front_Left_Link.stl"/>
      </geometry>
      <material name="">
        <color rgba="0.792156862745098 0.819607843137255 0.933333333333333 1"/>
      </material>
    </visual>
    <collision>
      <origin rpy="0 0 0" xyz="0 0.148 0"/>
      <geometry>
        <mesh filename="package://rogue/description/meshes/Driving_Front_Left_Link.stl"/>
      </geometry>
    </collision>
  </link>
  <joint name="Driving_Front_Left" type="continuous">
    <origin rpy="0 0 3.14159265358979" xyz="0 ${0.14261211817947+0.148} 0"/>
    <parent link="Steering_Front_Left_Link"/>
    <child link="Driving_Front_Left_Link"/>
    <axis xyz="1 0 0"/>
  </joint>
  <link name="Steering_Front_Right_Link">
    <inertial>
      <origin rpy="0 0 0" xyz="-0.00974656428371296 -0.171380762932291 -8.54871728961371E-15"/>
      <mass value="1.85682341940371"/>
      <inertia ixx="0.0307102115747056" ixy="-0.00225357611286932" ixz="-1.57031471972793E-14" iyy="0.0217734903548105" iyz="-1.99752053006014E-15" izz="0.0500272192704002"/>
    </inertial>
    <visual>
      <origin rpy="0 0 0" xyz="0 0 0"/>
      <geometry>
        <mesh filename="package://rogue/description/meshes/Steering_Front_Right_Link.stl"/>
      </geometry>
      <material name="">
        <color rgba="0.666666666666667 0.698039215686274 0.768627450980392 1"/>
      </material>
    </visual>
    <collision>
      <origin rpy="0 0 0" xyz="0 0 0"/>
      <geometry>
        <mesh filename="package://rogue/description/meshes/Steering_Front_Right_Link.stl"/>
      </geometry>
    </collision>
  </link>
  <joint name="Steering_Front_Right" type="continuous">
    <origin rpy="1.57827537993681 0 1.5707963267949" xyz="-0.539856087012609 0.308000000000008 -0.0842760180023664"/>
    <parent link="base_link"/>
    <child link="Steering_Front_Right_Link"/>
    <axis xyz="0 1 0"/>
  </joint>
  <link name="Driving_Front_Right_Link">
    <inertial>
      <origin rpy="0 0 0" xyz="0.000635564712824388 0.152474662096144 0.000103856662758472"/>
      <mass value="3.92591214810005"/>
      <inertia ixx="0.0405276513384967" ixy="-8.45389473903581E-07" ixz="3.83041770842588E-09" iyy="0.0313134736150523" iyz="8.54177538309055E-06" izz="0.0312863477526412"/>
    </inertial>
    <visual>
      <origin rpy="0 0 0" xyz="0 -0.148 0"/>
      <geometry>
        <mesh filename="package://rogue/description/meshes/Driving_Front_Right_Link.stl"/>
      </geometry>
      <material name="">
        <color rgba="0.792156862745098 0.819607843137255 0.933333333333333 1"/>
      </material>
    </visual>
    <collision>
      <origin rpy="0 0 0" xyz="0 -0.148 0"/>
      <geometry>
        <mesh filename="package://rogue/description/meshes/Driving_Front_Right_Link.stl"/>
      </geometry>
    </collision>
  </link>
  <joint name="Driving_Front_Right" type="continuous">
    <origin rpy="0 0 3.14159265358979" xyz="0 ${-0.142741590881956-0.148} 0"/>
    <parent link="Steering_Front_Right_Link"/>
    <child link="Driving_Front_Right_Link"/>
    <axis xyz="1 0 0"/>
  </joint>
  <link name="Driving_Left_Link">
    <inertial>
      <origin rpy="0 0 0" xyz="-0.134864435287178 0.000687652998535182 -0.000103856662875601"/>
      <mass value="3.9259121481001"/>
      <inertia ixx="0.0405276513384971" ixy="8.45389473657967E-07" ixz="-3.83041783364525E-09" iyy="0.0313134736150526" iyz="8.54177538309626E-06" izz="0.0312863477526416"/>
    </inertial>
    <visual>
      <origin rpy="0 0 0" xyz="0 0 0"/>
      <geometry>
        <mesh filename="package://rogue/description/meshes/Driving_Left_Link.stl"/>
      </geometry>
      <material name="">
        <color rgba="0.792156862745098 0.819607843137255 0.933333333333333 1"/>
      </material>
    </visual>
    <collision>
      <origin rpy="0 0 0" xyz="0 0 0"/>
      <geometry>
        <mesh filename="package://rogue/description/meshes/Driving_Left_Link.stl"/>
      </geometry>
    </collision>
  </link>
  <joint name="Driving_Left" type="continuous">
    <origin rpy="1.5707963267949 0 1.5707963267949" xyz="0.535731179493507 -0.172500000000432 -0.38861768424532"/>
    <parent link="base_link"/>
    <child link="Driving_Left_Link"/>
    <axis xyz="1 0 0"/>
  </joint>
  <link name="Driving_Right_Link">
    <inertial>
      <origin rpy="0 0 0" xyz="-0.134864435287174 -0.000687652998533683 0.00010385666287549"/>
      <mass value="3.92591214810012"/>
      <inertia ixx="0.0405276513384973" ixy="-8.45389473982144E-07" ixz="3.83041772531102E-09" iyy="0.0313134736150526" iyz="8.54177538295617E-06" izz="0.0312863477526417"/>
    </inertial>
    <visual>
      <origin rpy="0 0 0" xyz="0 0 0"/>
      <geometry>
        <mesh filename="package://rogue/description/meshes/Driving_Right_Link.stl"/>
      </geometry>
      <material name="">
        <color rgba="0.792156862745098 0.819607843137255 0.933333333333333 1"/>
      </material>
    </visual>
    <collision>
      <origin rpy="0 0 0" xyz="0 0 0"/>
      <geometry>
        <mesh filename="package://rogue/description/meshes/Driving_Right_Link.stl"/>
      </geometry>
    </collision>
  </link>
  <joint name="Driving_Right" type="continuous">
    <origin rpy="-1.5707963267949 0 -1.5707963267949" xyz="0.536022919102346 0.17249999999957 -0.388234906342967"/>
    <parent link="base_link"/>
    <child link="Driving_Right_Link"/>
    <axis xyz="1 0 0"/>
  </joint>
</robot>
