<?xml version="1.0" encoding="utf-8"?>
<!-- This URDF was automatically created by SolidWorks to URDF Exporter! Originally created by Stephen Brawner (brawner@gmail.com) 
     Commit Version: 1.6.0-4-g7f85cfe  Build Version: 1.6.7995.38578
     For more information, please see http://wiki.ros.org/sw_urdf_exporter -->
<robot
  name="rogue">
  <link
    name="base_link">
    <inertial>
      <origin
        xyz="0.103810599409774 -2.7109617373637E-09 -0.0838472970584355"
        rpy="0 0 0" />
      <mass
        value="7.01937426124387" />
      <inertia
        ixx="0.0741303779895859"
        ixy="1.44345389077846E-06"
        ixz="-0.00011285057172583"
        iyy="0.119368535310317"
        iyz="-1.75393886531914E-08"
        izz="0.147490279923879" />
    </inertial>
    <visual>
      <origin
        xyz="0 0 0"
        rpy="0 0 0" />
      <geometry>
        <mesh
          filename="package://rogue/meshes/base_link.STL" />
      </geometry>
      <material
        name="">
        <color
          rgba="0.792156862745098 0.819607843137255 0.933333333333333 1" />
      </material>
    </visual>
    <collision>
      <origin
        xyz="0 0 0"
        rpy="0 0 0" />
      <geometry>
        <mesh
          filename="package://rogue/meshes/base_link.STL" />
      </geometry>
    </collision>
  </link>
  <link
    name="Steering_Front_Left_Link">
    <inertial>
      <origin
        xyz="-0.244746564283713 0.0614701607897898 -0.000901258948528993"
        rpy="0 0 0" />
      <mass
        value="1.85682341940371" />
      <inertia
        ixx="0.0307102115747056"
        ixy="0.00225357611286934"
        ixz="1.56417982949755E-14"
        iyy="0.0217734903548105"
        iyz="-1.09539655991642E-15"
        izz="0.0500272192704002" />
    </inertial>
    <visual>
      <origin
        xyz="0 0 0"
        rpy="0 0 0" />
      <geometry>
        <mesh
          filename="package://rogue/meshes/Steering_Front_Left_Link.STL" />
      </geometry>
      <material
        name="">
        <color
          rgba="0.666666666666667 0.698039215686274 0.768627450980392 1" />
      </material>
    </visual>
    <collision>
      <origin
        xyz="0 0 0"
        rpy="0 0 0" />
      <geometry>
        <mesh
          filename="package://rogue/meshes/Steering_Front_Left_Link.STL" />
      </geometry>
    </collision>
  </link>
  <joint
    name="Steering_Front_Left"
    type="continuous">
    <origin
      xyz="-0.539929731609329 -0.542999999999972 -0.193804668520646"
      rpy="-1.5789896816345 0 -1.5707963267949" />
    <parent
      link="base_link" />
    <child
      link="Steering_Front_Left_Link" />
    <axis
      xyz="0 1 0" />
  </joint>
  <link
    name="Driving_Front_Left_Link">
    <inertial>
      <origin
        xyz="0.235635564712825 -0.0257443062896671 0.0757766920462269"
        rpy="0 0 0" />
      <mass
        value="3.92591214810011" />
      <inertia
        ixx="0.0405276513384971"
        ixy="2.58229478601455E-07"
        ixz="-8.04994143480363E-07"
        iyy="0.0312939821707009"
        iyz="-1.48918689712807E-05"
        izz="0.0313058391969932" />
    </inertial>
    <visual>
      <origin
        xyz="0 0 0"
        rpy="0 0 0" />
      <geometry>
        <mesh
          filename="package://rogue/meshes/Driving_Front_Left_Link.STL" />
      </geometry>
      <material
        name="">
        <color
          rgba="0.792156862745098 0.819607843137255 0.933333333333333 1" />
      </material>
    </visual>
    <collision>
      <origin
        xyz="0 0 0"
        rpy="0 0 0" />
      <geometry>
        <mesh
          filename="package://rogue/meshes/Driving_Front_Left_Link.STL" />
      </geometry>
    </collision>
  </link>
  <joint
    name="Driving_Front_Left"
    type="continuous">
    <origin
      xyz="0 0.105281491318534 0"
      rpy="1.25585118201626 0 3.14159265358979" />
    <parent
      link="Steering_Front_Left_Link" />
    <child
      link="Driving_Front_Left_Link" />
    <axis
      xyz="0 0.309764314615681 -0.95081337253463" />
  </joint>
  <link
    name="Steering_Front_Right_Link">
    <inertial>
      <origin
        xyz="0.225253435716287 -0.0613838394109246 -0.000822688175889374"
        rpy="0 0 0" />
      <mass
        value="1.85682341940371" />
      <inertia
        ixx="0.0307102115747056"
        ixy="-0.00225357611286932"
        ixz="-1.57029811788216E-14"
        iyy="0.0217734903548105"
        iyz="-1.9973172421528E-15"
        izz="0.0500272192704002" />
    </inertial>
    <visual>
      <origin
        xyz="0 0 0"
        rpy="0 0 0" />
      <geometry>
        <mesh
          filename="package://rogue/meshes/Steering_Front_Right_Link.STL" />
      </geometry>
      <material
        name="">
        <color
          rgba="0.666666666666667 0.698039215686274 0.768627450980392 1" />
      </material>
    </visual>
    <collision>
      <origin
        xyz="0 0 0"
        rpy="0 0 0" />
      <geometry>
        <mesh
          filename="package://rogue/meshes/Steering_Front_Right_Link.STL" />
      </geometry>
    </collision>
  </link>
  <joint
    name="Steering_Front_Right"
    type="continuous">
    <origin
      xyz="-0.539856087012609 0.0730000000000078 -0.194276018002367"
      rpy="1.57827537993681 0 1.5707963267949" />
    <parent
      link="base_link" />
    <child
      link="Steering_Front_Right_Link" />
    <axis
      xyz="0 1 0" />
  </joint>
  <link
    name="Driving_Front_Right_Link">
    <inertial>
      <origin
        xyz="-0.234364435287176 0.0237233963684859 0.0746409006247968"
        rpy="0 0 0" />
      <mass
        value="3.92591214810005" />
      <inertia
        ixx="0.0405276513384966"
        ixy="-2.52326125562653E-07"
        ixz="-8.06864028845856E-07"
        iyy="0.0312838919770476"
        iyz="5.62193973789246E-07"
        izz="0.0313159293906459" />
    </inertial>
    <visual>
      <origin
        xyz="0 0 0"
        rpy="0 0 0" />
      <geometry>
        <mesh
          filename="package://rogue/meshes/Driving_Front_Right_Link.STL" />
      </geometry>
      <material
        name="">
        <color
          rgba="0.792156862745098 0.819607843137255 0.933333333333333 1" />
      </material>
    </visual>
    <collision>
      <origin
        xyz="0 0 0"
        rpy="0 0 0" />
      <geometry>
        <mesh
          filename="package://rogue/meshes/Driving_Front_Right_Link.STL" />
      </geometry>
    </collision>
  </link>
  <joint
    name="Driving_Front_Right"
    type="continuous">
    <origin
      xyz="0 -0.10690236537747 0"
      rpy="-1.27223789169551 0 3.14159265358979" />
    <parent
      link="Steering_Front_Right_Link" />
    <child
      link="Driving_Front_Right_Link" />
    <axis
      xyz="0 0.294142720525736 0.955761507888719" />
  </joint>
  <link
    name="Driving_Left_Link">
    <inertial>
      <origin
        xyz="0.100135564712824 0.102080903099441 -0.0427931832764656"
        rpy="0 0 0" />
      <mass
        value="3.9259121481001" />
      <inertia
        ixx="0.0405276513384971"
        ixy="7.78482858174691E-07"
        ixz="-3.29639915363223E-07"
        iyy="0.0313155171694435"
        iyz="-3.65412601208582E-06"
        izz="0.0312843041982508" />
    </inertial>
    <visual>
      <origin
        xyz="0 0 0"
        rpy="0 0 0" />
      <geometry>
        <mesh
          filename="package://rogue/meshes/Driving_Left_Link.STL" />
      </geometry>
      <material
        name="">
        <color
          rgba="0.792156862745098 0.819607843137255 0.933333333333333 1" />
      </material>
    </visual>
    <collision>
      <origin
        xyz="0 0 0"
        rpy="0 0 0" />
      <geometry>
        <mesh
          filename="package://rogue/meshes/Driving_Left_Link.STL" />
      </geometry>
    </collision>
  </link>
  <joint
    name="Driving_Left"
    type="continuous">
    <origin
      xyz="0.535731179493507 -0.407500000000434 -0.49861768424532"
      rpy="1.96681303566779 0 1.5707963267949" />
    <parent
      link="base_link" />
    <child
      link="Driving_Left_Link" />
    <axis
      xyz="1 0 0" />
  </joint>
  <link
    name="Driving_Right_Link">
    <inertial>
      <origin
        xyz="-0.307364435286744 -0.106845153056515 -0.0289115994171902"
        rpy="0 0 0" />
      <mass
        value="3.92591214810012" />
      <inertia
        ixx="0.0405276513384973"
        ixy="-8.16838012431588E-07"
        ixz="-2.17884593916795E-07"
        iyy="0.0313072889431169"
        iyz="1.42294174064108E-05"
        izz="0.0312925324245774" />
    </inertial>
    <visual>
      <origin
        xyz="0 0 0"
        rpy="0 0 0" />
      <geometry>
        <mesh
          filename="package://rogue/meshes/Driving_Right_Link.STL" />
      </geometry>
      <material
        name="">
        <color
          rgba="0.792156862745098 0.819607843137255 0.933333333333333 1" />
      </material>
    </visual>
    <collision>
      <origin
        xyz="0 0 0"
        rpy="0 0 0" />
      <geometry>
        <mesh
          filename="package://rogue/meshes/Driving_Right_Link.STL" />
      </geometry>
    </collision>
  </link>
  <joint
    name="Driving_Right"
    type="continuous">
    <origin
      xyz="0.536022919102397 0 -0.498234906342967"
      rpy="-1.8359994985479 0 -1.5707963267949" />
    <parent
      link="base_link" />
    <child
      link="Driving_Right_Link" />
    <axis
      xyz="1 0 0" />
  </joint>
</robot>